Traceback (most recent call last):
  File "C:\Users\Keyla Alba\.conda\envs\tf_gpu_py39\lib\site-packages\jupyter_core\utils\__init__.py", line 154, in wrapped
    asyncio.get_running_loop()
RuntimeError: no running event loop

During handling of the above exception, another exception occurred:

Traceback (most recent call last):
  File "C:\Users\Keyla Alba\.conda\envs\tf_gpu_py39\lib\site-packages\jupyter_cache\executors\utils.py", line 58, in single_nb_execution
    executenb(
  File "C:\Users\Keyla Alba\.conda\envs\tf_gpu_py39\lib\site-packages\nbclient\client.py", line 1319, in execute
    return NotebookClient(nb=nb, resources=resources, km=km, **kwargs).execute()
  File "C:\Users\Keyla Alba\.conda\envs\tf_gpu_py39\lib\site-packages\jupyter_core\utils\__init__.py", line 158, in wrapped
    return loop.run_until_complete(inner)
  File "C:\Users\Keyla Alba\.conda\envs\tf_gpu_py39\lib\asyncio\base_events.py", line 647, in run_until_complete
    return future.result()
  File "C:\Users\Keyla Alba\.conda\envs\tf_gpu_py39\lib\site-packages\nbclient\client.py", line 709, in async_execute
    await self.async_execute_cell(
  File "C:\Users\Keyla Alba\.conda\envs\tf_gpu_py39\lib\site-packages\nbclient\client.py", line 1062, in async_execute_cell
    await self._check_raise_for_error(cell, cell_index, exec_reply)
  File "C:\Users\Keyla Alba\.conda\envs\tf_gpu_py39\lib\site-packages\nbclient\client.py", line 918, in _check_raise_for_error
    raise CellExecutionError.from_cell_and_msg(cell, exec_reply_content)
nbclient.exceptions.CellExecutionError: An error occurred while executing the following cell:
------------------
fig_INMET = px.line(
    df_INMET,
    x='datetime',
    y='RADIACAO_GLOBAL',
    title='RadiaciÃ³n Global (KJ/mÂ²) por Hora INMET (2019 a Febrero 2025)',
    labels={
        'datetime': 'Fecha y Hora',
        'RADIACAO_GLOBAL': 'RadiaciÃ³n (KJ/mÂ²)'
    }
)
fig_INMET.update_layout(template='plotly_white', width=1100, height=500)
fig_INMET.show()
------------------


[1;31m---------------------------------------------------------------------------[0m
[1;31mNameError[0m                                 Traceback (most recent call last)
Cell [1;32mIn[1], line 1[0m
[1;32m----> 1[0m fig_INMET [38;5;241m=[39m [43mpx[49m[38;5;241m.[39mline(
[0;32m      2[0m     df_INMET,
[0;32m      3[0m     x[38;5;241m=[39m[38;5;124m'[39m[38;5;124mdatetime[39m[38;5;124m'[39m,
[0;32m      4[0m     y[38;5;241m=[39m[38;5;124m'[39m[38;5;124mRADIACAO_GLOBAL[39m[38;5;124m'[39m,
[0;32m      5[0m     title[38;5;241m=[39m[38;5;124m'[39m[38;5;124mRadiaciÃ³n Global (KJ/mÂ²) por Hora INMET (2019 a Febrero 2025)[39m[38;5;124m'[39m,
[0;32m      6[0m     labels[38;5;241m=[39m{
[0;32m      7[0m         [38;5;124m'[39m[38;5;124mdatetime[39m[38;5;124m'[39m: [38;5;124m'[39m[38;5;124mFecha y Hora[39m[38;5;124m'[39m,
[0;32m      8[0m         [38;5;124m'[39m[38;5;124mRADIACAO_GLOBAL[39m[38;5;124m'[39m: [38;5;124m'[39m[38;5;124mRadiaciÃ³n (KJ/mÂ²)[39m[38;5;124m'[39m
[0;32m      9[0m     }
[0;32m     10[0m )
[0;32m     11[0m fig_INMET[38;5;241m.[39mupdate_layout(template[38;5;241m=[39m[38;5;124m'[39m[38;5;124mplotly_white[39m[38;5;124m'[39m, width[38;5;241m=[39m[38;5;241m1100[39m, height[38;5;241m=[39m[38;5;241m500[39m)
[0;32m     12[0m fig_INMET[38;5;241m.[39mshow()

[1;31mNameError[0m: name 'px' is not defined

